<?xml version="1.0" ?>
<!-- =================================================================================== -->
<!-- |    This document was autogenerated by xacro from model.sdf.xacro                | -->
<!-- |    EDITING THIS FILE BY HAND IS NOT RECOMMENDED                                 | -->
<!-- =================================================================================== -->
<sdf version="1.6">
  <model name="openbase_omni3_model">
    <link name="body_link">
      <pose>0 0 0 0 0 0</pose>
      <inertial>
        <mass>0.07862944645</mass>
        <pose>0 0 0 0 0 0</pose>
        <inertia>
          <ixx>0.00002035985530754</ixx>
          <ixy>0</ixy>
          <ixz>0</ixz>
          <iyy>0.00002035985530754</iyy>
          <iyz>0</iyz>
          <izz>0.00003945961663220</izz>
        </inertia>
      </inertial>
      <visual name="visual">
        <pose>0 0 0 0 0 0</pose>
        <geometry>
          <mesh>
            <uri>model://omni_wheel/body.stl</uri>
            <scale>1 1 1</scale>
          </mesh>
        </geometry>
        <material>
          <lighting>true</lighting>
          <script>
            <uri>file://media/materials/scripts/gazebo.material</uri>
            <name>Gazebo/Grey</name>
          </script>
          <ambient>1 1 1 1</ambient>
          <diffuse>0.7 0.7 0.7 1</diffuse>
          <specular>0.01 0.01 0.01 1</specular>
          <emissive>0 0 0 1</emissive>
          <shader type="vertex">
            <normal_map>__default__</normal_map>
          </shader>
        </material>
      </visual>
      <collision name="collision">
        <laser_retro>0</laser_retro>
        <max_contacts>10</max_contacts>
        <pose>0 0 0 0 0 0</pose>
        <geometry>
          <mesh>
            <uri>model://omni_wheel/body.stl</uri>
            <scale>1 1 1</scale>
          </mesh>
        </geometry>
        <surface>
          <friction>
            <ode>
              <mu>1</mu>
              <mu2>1</mu2>
              <fdir1>0 0 0</fdir1>
              <slip1>0</slip1>
              <slip2>0</slip2>
            </ode>
            <torsional>
              <coefficient>1</coefficient>
              <patch_radius>0</patch_radius>
              <surface_radius>0</surface_radius>
              <use_patch_radius>true</use_patch_radius>
              <ode>
                <slip>0</slip>
              </ode>
            </torsional>
          </friction>
          <bounce>
            <restitution_coefficient>0</restitution_coefficient>
            <threshold>1e+06</threshold>
          </bounce>
          <contact>
            <collide_without_contact>false</collide_without_contact>
            <collide_bitmask>1</collide_bitmask>
            <ode>
              <soft_cfm>0</soft_cfm>
              <soft_erp>0.2</soft_erp>
              <kp>1e+13</kp>
              <kd>1</kd>
              <max_vel>0.01</max_vel>
              <min_depth>0</min_depth>
            </ode>
            <bullet>
              <split_impulse>true</split_impulse>
              <split_impulse_penetration_threshold>-0.01</split_impulse_penetration_threshold>
              <soft_cfm>0</soft_cfm>
              <soft_erp>0.2</soft_erp>
              <kp>1e+13</kp>
              <kd>1</kd>
            </bullet>
          </contact>
        </surface>
      </collision>
    </link>
    <include>
      <name>omni_wheel_left_model</name>
      <uri>model://omni_wheel</uri>
      <pose>-0.03464101615 0.02 0 0 -0 2.617993877991494</pose>
    </include>
    <include>
      <name>omni_wheel_right_model</name>
      <uri>model://omni_wheel</uri>
      <pose>0 -0.04 0 0 -0 4.71238898038469</pose>
    </include>
    <include>
      <name>omni_wheel_back_model</name>
      <uri>model://omni_wheel</uri>
      <pose>0.03464101615 0.02 0 0 -0 0.52359877559829</pose>
    </include>
    <joint name="left_joint" type="revolute">
      <parent>body_link</parent>
      <child>omni_wheel_left_model::omni_wheel_rim_link</child>
      <pose frame="">0 0 0 3.14159 -1.57079 3.14159</pose>
      <axis>
        <xyz>0 0 1</xyz>
        <use_parent_model_frame>0</use_parent_model_frame>
        <limit>
          <lower>-1.79769e+308</lower>
          <upper>1.79769e+308</upper>
          <effort>-1</effort>
          <velocity>-1</velocity>
        </limit>
        <dynamics>
          <spring_reference>0</spring_reference>
          <spring_stiffness>0</spring_stiffness>
          <damping>0</damping>
          <friction>0.0001</friction>
        </dynamics>
      </axis>
      <physics>
        <ode>
          <limit>
            <cfm>0</cfm>
            <erp>0.2</erp>
          </limit>
          <suspension>
            <cfm>0</cfm>
            <erp>0.2</erp>
          </suspension>
        </ode>
      </physics>
    </joint>
    <joint name="right_joint" type="revolute">
      <parent>body_link</parent>
      <child>omni_wheel_right_model::omni_wheel_rim_link</child>
      <pose frame="">0 0 0 3.14159 -1.57079 3.14159</pose>
      <axis>
        <xyz>0 0 1</xyz>
        <use_parent_model_frame>0</use_parent_model_frame>
        <limit>
          <lower>-1.79769e+308</lower>
          <upper>1.79769e+308</upper>
          <effort>-1</effort>
          <velocity>-1</velocity>
        </limit>
        <dynamics>
          <spring_reference>0</spring_reference>
          <spring_stiffness>0</spring_stiffness>
          <damping>0</damping>
          <friction>0.0001</friction>
        </dynamics>
      </axis>
      <physics>
        <ode>
          <limit>
            <cfm>0</cfm>
            <erp>0.2</erp>
          </limit>
          <suspension>
            <cfm>0</cfm>
            <erp>0.2</erp>
          </suspension>
        </ode>
      </physics>
    </joint>
    <joint name="back_joint" type="revolute">
      <parent>body_link</parent>
      <child>omni_wheel_back_model::omni_wheel_rim_link</child>
      <pose frame="">0 0 0 3.14159 -1.57079 3.14159</pose>
      <axis>
        <xyz>0 0 1</xyz>
        <use_parent_model_frame>0</use_parent_model_frame>
        <limit>
          <lower>-1.79769e+308</lower>
          <upper>1.79769e+308</upper>
          <effort>-1</effort>
          <velocity>-1</velocity>
        </limit>
        <dynamics>
          <spring_reference>0</spring_reference>
          <spring_stiffness>0</spring_stiffness>
          <damping>0</damping>
          <friction>0.0001</friction>
        </dynamics>
      </axis>
      <physics>
        <ode>
          <limit>
            <cfm>0</cfm>
            <erp>0.2</erp>
          </limit>
          <suspension>
            <cfm>0</cfm>
            <erp>0.2</erp>
          </suspension>
        </ode>
      </physics>
    </joint>
    <plugin filename="libgazebo_ros_omni_drive.so" name="omni_drive">
      <joint>left_joint</joint>
      <joint>right_joint</joint>
      <joint>back_joint</joint>
    </plugin>
  </model>
</sdf>
