<?xml version='1.0'?>
<sdf version='1.6' xmlns:xacro="http://www.ros.org/wiki/xacro">
	<model name='simple_omni_wheel_model'>
		<xacro:macro name="omni_wheel_rim_link" params="name">
			<link name='${name}'>
				<pose>0 0 0 0 0 0</pose>
				<inertial>
					<mass>0.00835758</mass>
					<inertia>
						<ixx>9.40333e-07</ixx>
						<ixy>0</ixy>
						<ixz>0</ixz>
						<iyy>6.63684e-07</iyy>
						<iyz>0</iyz>
						<izz>6.63684e-07</izz>
					</inertia>
					<pose>0 -0.000343 0 0 0 0</pose>
				</inertial>
				<visual name='visual'>
					<pose>0 0 0 0 ${pi/2} 0</pose>
					<geometry>
						<cylinder>
							<radius>0.018</radius>
							<length>0.01</length>
						</cylinder>
					</geometry>
					<material>
						<lighting>true</lighting>
						<script>
							<uri>file://media/materials/scripts/gazebo.material</uri>
							<name>Gazebo/Grey</name>
						</script>
						<ambient>0.3 0.3 0.3 1</ambient>
						<diffuse>0.7 0.7 0.7 1</diffuse>
						<specular>0.01 0.01 0.01 1</specular>
						<emissive>0 0 0 1</emissive>
						<shader type='vertex'>
							<normal_map>__default__</normal_map>
						</shader>
					</material>
				</visual>
				<collision name='collision'>
					<laser_retro>0</laser_retro>
					<max_contacts>10</max_contacts>
					<pose>0 0 0 0 ${pi/2} 0</pose>
					<geometry>
						<cylinder>
							<radius>0.018</radius>
							<length>0.01</length>
						</cylinder>
					</geometry>
					<surface>
						<friction>
							<ode>
								<mu>1</mu>
								<mu2>1</mu2>
								<fdir1>0 0 0</fdir1>
								<slip1>0</slip1>
								<slip2>0</slip2>
							</ode>
							<torsional>
								<coefficient>1</coefficient>
								<patch_radius>0</patch_radius>
								<surface_radius>0</surface_radius>
								<use_patch_radius>true</use_patch_radius>
								<ode>
									<slip>0</slip>
								</ode>
							</torsional>
						</friction>
						<bounce>
							<restitution_coefficient>0</restitution_coefficient>
							<threshold>1e+06</threshold>
						</bounce>
						<contact>
							<collide_without_contact>false</collide_without_contact>
							<collide_bitmask>1</collide_bitmask>
							<ode>
								<soft_cfm>0</soft_cfm>
								<soft_erp>0.2</soft_erp>
								<kp>1e+13</kp>
								<kd>1</kd>
								<max_vel>0.01</max_vel>
								<min_depth>0</min_depth>
							</ode>
							<bullet>
								<split_impulse>true</split_impulse>
								<split_impulse_penetration_threshold>-0.01</split_impulse_penetration_threshold>
								<soft_cfm>0</soft_cfm>
								<soft_erp>0.2</soft_erp>
								<kp>1e+13</kp>
								<kd>1</kd>
							</bullet>
						</contact>
					</surface>
				</collision>
			</link>
		</xacro:macro>

		<xacro:macro name="omni_wheel_roller_link" params="name *pose">
			<link name='${name}'>
				<xacro:insert_block name="pose"/>
				<inertial>
					<mass>0.00113845</mass>
					<pose>0 0 0 0 0 0</pose>
					<inertia>
						<ixx>2.53776e-08</ixx>
						<ixy>0</ixy>
						<ixz>0</ixz>
						<iyy>2.53776e-08</iyy>
						<iyz>0</iyz>
						<izz>1.47666e-08</izz>
					</inertia>
				</inertial>
				<visual name='visual'>
					<pose>0 0 0 0 0 0</pose>
					<geometry>
						<cylinder>
							<radius>0.0049</radius>
							<length>0.01</length>
						</cylinder>
					</geometry>
					<material>
						<lighting>true</lighting>
						<script>
							<uri>file://media/materials/scripts/gazebo.material</uri>
							<name>Gazebo/Grey</name>
						</script>
						<ambient>0.03 0.03 0.03 1</ambient>
						<diffuse>0.07 0.07 0.07 1</diffuse>
						<specular>0.001 0.001 0.001 1</specular>
						<emissive>0 0 0 1</emissive>
						<shader type='vertex'>
							<normal_map>__default__</normal_map>
						</shader>
					</material>
				</visual>
				<collision name='collision'>
					<laser_retro>0</laser_retro>
					<max_contacts>10</max_contacts>
					<pose>0 0 0 0 0 0</pose>
					<geometry>
						<cylinder>
							<radius>0.0049</radius>
							<length>0.01</length>
						</cylinder>
					</geometry>
					<surface>
						<friction>
							<ode>
								<mu>1</mu>
								<mu2>1</mu2>
								<fdir1>0 0 0</fdir1>
								<slip1>0</slip1>
								<slip2>0</slip2>
							</ode>
							<torsional>
								<coefficient>1</coefficient>
								<patch_radius>0</patch_radius>
								<surface_radius>0</surface_radius>
								<use_patch_radius>true</use_patch_radius>
								<ode>
									<slip>0</slip>
								</ode>
							</torsional>
						</friction>
						<bounce>
							<restitution_coefficient>0</restitution_coefficient>
							<threshold>1e+06</threshold>
						</bounce>
						<contact>
							<collide_without_contact>false</collide_without_contact>
							<collide_bitmask>1</collide_bitmask>
							<ode>
								<soft_cfm>0</soft_cfm>
								<soft_erp>0.2</soft_erp>
								<kp>1e+13</kp>
								<kd>1</kd>
								<max_vel>0.01</max_vel>
								<min_depth>0</min_depth>
							</ode>
							<bullet>
								<split_impulse>true</split_impulse>
								<split_impulse_penetration_threshold>-0.01</split_impulse_penetration_threshold>
								<soft_cfm>0</soft_cfm>
								<soft_erp>0.2</soft_erp>
								<kp>1e+13</kp>
								<kd>1</kd>
							</bullet>
						</contact>
					</surface>
				</collision>
			</link>
		</xacro:macro>

		<xacro:macro name="omni_wheel_joint" params="name child">
			<joint name='${name}' type='revolute'>
				<parent>omni_wheel_rim_link</parent>
				<child>${child}</child>
				<pose>0 0 0 0 0 ${pi/2}</pose>
				<axis>
					<xyz>0 0 1</xyz>
					<limit>
						<lower>-1.79769e+308</lower>
						<upper>1.79769e+308</upper>
						<effort>-1</effort>
						<velocity>-1</velocity>
					</limit>
					<dynamics>
						<spring_reference>0</spring_reference>
						<spring_stiffness>0</spring_stiffness>
						<damping>0</damping>
						<friction>0.001</friction>
					</dynamics>
				</axis>
				<physics>
					<ode>
						<limit>
							<cfm>0</cfm>
							<erp>0.2</erp>
						</limit>
						<suspension>
							<cfm>0</cfm>
							<erp>0.2</erp>
						</suspension>
					</ode>
				</physics>
			</joint>
		</xacro:macro>

		<xacro:omni_wheel_rim_link name="omni_wheel_rim_link"/>

		<xacro:omni_wheel_roller_link name="omni_wheel_roller_e_link">
			<pose>-0.0055 0.01355 0 0 -0 0</pose>
		</xacro:omni_wheel_roller_link>
		<xacro:omni_wheel_roller_link name="omni_wheel_roller_ne_link">
			<pose>0.0055 0.009581 0.009581 ${pi*1/4} -0 0</pose>
		</xacro:omni_wheel_roller_link>
		<xacro:omni_wheel_roller_link name="omni_wheel_roller_n_link">
			<pose>-0.0055 0 0.01355 ${pi*2/4} -0 0</pose>
		</xacro:omni_wheel_roller_link>
		<xacro:omni_wheel_roller_link name="omni_wheel_roller_nw_link">
			<pose>0.0055 -0.009581 0.009581 ${pi*3/4} -0 0</pose>
		</xacro:omni_wheel_roller_link>
		<xacro:omni_wheel_roller_link name="omni_wheel_roller_w_link">
			<pose>-0.0055 -0.01355 0 ${-pi} 0 0</pose>
		</xacro:omni_wheel_roller_link>
		<xacro:omni_wheel_roller_link name="omni_wheel_roller_sw_link">
			<pose>0.0055 -0.009581 -0.009581 ${-pi*3/4} 0 0</pose>
		</xacro:omni_wheel_roller_link>
		<xacro:omni_wheel_roller_link name="omni_wheel_roller_s_link">
			<pose>-0.0055 0 -0.01355 ${-pi*2/4} 0 0</pose>
		</xacro:omni_wheel_roller_link>
		<xacro:omni_wheel_roller_link name="omni_wheel_roller_se_link">
			<pose>0.0055 0.009581 -0.009581 ${-pi*1/4} 0 0</pose>
		</xacro:omni_wheel_roller_link>

		<xacro:omni_wheel_joint name="omni_wheel_s_joint" child="omni_wheel_roller_s_link"/>
		<xacro:omni_wheel_joint name="omni_wheel_se_joint" child="omni_wheel_roller_se_link"/>
		<xacro:omni_wheel_joint name="omni_wheel_e_joint" child="omni_wheel_roller_e_link"/>
		<xacro:omni_wheel_joint name="omni_wheel_ne_joint" child="omni_wheel_roller_ne_link"/>
		<xacro:omni_wheel_joint name="omni_wheel_n_joint" child="omni_wheel_roller_n_link"/>
		<xacro:omni_wheel_joint name="omni_wheel_nw_joint" child="omni_wheel_roller_nw_link"/>
		<xacro:omni_wheel_joint name="omni_wheel_w_joint" child="omni_wheel_roller_w_link"/>
		<xacro:omni_wheel_joint name="omni_wheel_sw_joint" child="omni_wheel_roller_sw_link"/>

	</model>
</sdf>
