<?xml version="1.0"?>
<sdf version="1.7" xmlns:xacro="http://www.ros.org/wiki/xacro">
	<xacro:macro name="omni_wheel_rim_link" params="name">
		<link name="${name}">
			<pose>0 0 0 ${pi/2} 0 0</pose>
			<inertial>
				<mass>0.00835758</mass>
				<inertia>
					<ixx>6.63684e-07</ixx>
					<ixy>0</ixy>
					<ixz>0</ixz>
					<iyy>6.63684e-07</iyy>
					<iyz>0</iyz>
					<izz>9.40333e-07</izz>
				</inertia>
			</inertial>
			<visual name="visual">
				<geometry>
					<cylinder>
						<radius>0.018</radius>
						<length>0.01</length>
					</cylinder>
				</geometry>
				<material>
					<script>
						<uri>file://media/materials/scripts/gazebo.material</uri>
						<name>Gazebo/Grey</name>
					</script>
				</material>
			</visual>
			<collision name="collision">
				<geometry>
					<cylinder>
						<radius>0.018</radius>
						<length>0.01</length>
					</cylinder>
				</geometry>
				<surface>
					<friction>
						<ode>
							<mu>1</mu>
							<mu2>1</mu2>
							<fdir1>0 0 0</fdir1>
							<slip1>0</slip1>
							<slip2>0</slip2>
						</ode>
					</friction>
				</surface>
			</collision>
		</link>
	</xacro:macro>

	<xacro:macro name="omni_wheel_roller_link" params="name *pose">
		<link name="${name}">
			<xacro:insert_block name="pose"/>
			<inertial>
				<mass>0.00313845</mass>
				<inertia>
					<ixx>2.53776e-07</ixx>
					<ixy>0</ixy>
					<ixz>0</ixz>
					<iyy>2.53776e-07</iyy>
					<iyz>0</iyz>
					<izz>1.47666e-07</izz>
				</inertia>
			</inertial>
			<visual name="visual">
				<geometry>
					<cylinder>
						<radius>0.0049</radius>
						<length>0.01</length>
					</cylinder>
				</geometry>
				<material>
					<script>
						<uri>file://media/materials/scripts/gazebo.material</uri>
						<name>Gazebo/Black</name>
					</script>
				</material>
			</visual>
			<collision name="collision">
				<geometry>
					<cylinder>
						<radius>0.0049</radius>
						<length>0.01</length>
					</cylinder>
				</geometry>
				<surface>
					<friction>
						<ode>
							<mu>1</mu>
							<mu2>1</mu2>
							<fdir1>0 0 0</fdir1>
							<slip1>0</slip1>
							<slip2>0</slip2>
						</ode>
					</friction>
				</surface>
			</collision>
		</link>
	</xacro:macro>

	<xacro:macro name="omni_wheel_joint" params="name rim_link_name roller_link_name">
		<joint name="${name}" type="revolute">
			<parent>${rim_link_name}</parent>
			<child>${roller_link_name}</child>
			<axis>
				<xyz>0 0 1</xyz>
				<dynamics>
					<spring_reference>0</spring_reference>
					<spring_stiffness>0</spring_stiffness>
					<damping>0</damping>
					<friction>0.001</friction>
				</dynamics>
			</axis>
		</joint>
	</xacro:macro>

	<xacro:macro name="omni_wheel_model" params="name">
		<model name="${model_name}">
			<xacro:omni_wheel_rim_link name="rim_link"/>

			<xacro:omni_wheel_roller_link name="roller_link_0">
				<pose>0.01355 0 -0.0055 0 0 0</pose>
			</xacro:omni_wheel_roller_link>

			<xacro:omni_wheel_joint name="omni_wheel_joint_0" rim_link_name="rim_link" roller_link_name="roller_link_0"/>
		</model>
	</xacro:macro>

	<!--
	<xacro:omni_wheel_rim_link name="omni_wheel_rim_link"/>

	<xacro:omni_wheel_roller_link name="omni_wheel_roller_e_link">
		<pose>-0.0055 0.01355 0 0 -0 0</pose>
	</xacro:omni_wheel_roller_link>
	<xacro:omni_wheel_roller_link name="omni_wheel_roller_n_link">
		<pose>-0.0055 0 0.01355 ${pi*2/4} -0 0</pose>
	</xacro:omni_wheel_roller_link>
	<xacro:omni_wheel_roller_link name="omni_wheel_roller_w_link">
		<pose>-0.0055 -0.01355 0 ${-pi} 0 0</pose>
	</xacro:omni_wheel_roller_link>
	<xacro:omni_wheel_roller_link name="omni_wheel_roller_s_link">
		<pose>-0.0055 0 -0.01355 ${-pi*2/4} 0 0</pose>
	</xacro:omni_wheel_roller_link>
	<xacro:omni_wheel_roller_link name="omni_wheel_roller_ne_link">
		<pose>0.0055 0.009581 0.009581 ${pi*1/4} -0 0</pose>
	</xacro:omni_wheel_roller_link>
	<xacro:omni_wheel_roller_link name="omni_wheel_roller_nw_link">
		<pose>0.0055 -0.009581 0.009581 ${pi*3/4} -0 0</pose>
	</xacro:omni_wheel_roller_link>
	<xacro:omni_wheel_roller_link name="omni_wheel_roller_sw_link">
		<pose>0.0055 -0.009581 -0.009581 ${-pi*3/4} 0 0</pose>
	</xacro:omni_wheel_roller_link>
	<xacro:omni_wheel_roller_link name="omni_wheel_roller_se_link">
		<pose>0.0055 0.009581 -0.009581 ${-pi*1/4} 0 0</pose>
	</xacro:omni_wheel_roller_link>

	<xacro:omni_wheel_joint name="omni_wheel_s_joint" child="omni_wheel_roller_s_link"/>
	<xacro:omni_wheel_joint name="omni_wheel_se_joint" child="omni_wheel_roller_se_link"/>
	<xacro:omni_wheel_joint name="omni_wheel_e_joint" child="omni_wheel_roller_e_link"/>
	<xacro:omni_wheel_joint name="omni_wheel_ne_joint" child="omni_wheel_roller_ne_link"/>
	<xacro:omni_wheel_joint name="omni_wheel_n_joint" child="omni_wheel_roller_n_link"/>
	<xacro:omni_wheel_joint name="omni_wheel_nw_joint" child="omni_wheel_roller_nw_link"/>
	<xacro:omni_wheel_joint name="omni_wheel_w_joint" child="omni_wheel_roller_w_link"/>
	<xacro:omni_wheel_joint name="omni_wheel_sw_joint" child="omni_wheel_roller_sw_link"/>
	-->
</sdf>
