<?xml version='1.0'?>
<sdf version='1.6' xmlns:xacro="http://www.ros.org/wiki/xacro">
	<model name='multi_laser_model'>

		<pose>0 0 0.03 0 0 0</pose>

		<include>
			<name>damped_omni4_model</name>
			<uri>model://damped_omni4</uri>
		</include>

		<link name="lidar_link1">
			<pose>0.1 0 0.06 0 0 0</pose>
			<inertial>
				<mass>0.001</mass>
				<inertia>
					<ixx>0.00001</ixx>
					<ixy>0</ixy>
					<ixz>0</ixz>
					<iyy>0.00001</iyy>
					<iyz>0</iyz>
					<izz>0.00001</izz>
				</inertia>
			</inertial>
			<sensor name="lidar" type="ray">
				<always_on>true</always_on>
				<visualize>true</visualize>
				<update_rate>5</update_rate>
				<ray>
					<scan>
						<horizontal>
							<samples>360</samples>
							<resolution>1.000000</resolution>
							<min_angle>-0.785398</min_angle>
							<max_angle>0.785398</max_angle>
						</horizontal>
					</scan>
					<range>
						<min>0.060000</min>
						<max>3.5</max>
						<resolution>0.015000</resolution>
					</range>
					<noise>
						<type>gaussian</type>
						<mean>0.0</mean>
						<stddev>0.01</stddev>
					</noise>
				</ray>
				<plugin name="scan1" filename="libgazebo_ros_ray_sensor.so">
					<ros>
						<remapping>~/out:=scan1</remapping>
					</ros>
					<output_type>sensor_msgs/LaserScan</output_type>
					<frame_name>lidar_link1</frame_name>
				</plugin>
			</sensor>
		</link>

		<link name="lidar_link2">
			<pose>-0.1 0 0.06 0 0 3.1415</pose>
			<inertial>
				<mass>0.001</mass>
				<inertia>
					<ixx>0.00001</ixx>
					<ixy>0</ixy>
					<ixz>0</ixz>
					<iyy>0.00001</iyy>
					<iyz>0</iyz>
					<izz>0.00001</izz>
				</inertia>
			</inertial>
			<sensor name="lidar" type="ray">
				<always_on>true</always_on>
				<visualize>true</visualize>
				<update_rate>5</update_rate>
				<ray>
					<scan>
						<horizontal>
							<samples>360</samples>
							<resolution>1.000000</resolution>
							<min_angle>-0.785398</min_angle>
							<max_angle>0.785398</max_angle>
						</horizontal>
					</scan>
					<range>
						<min>0.060000</min>
						<max>3.5</max>
						<resolution>0.015000</resolution>
					</range>
					<noise>
						<type>gaussian</type>
						<mean>0.0</mean>
						<stddev>0.01</stddev>
					</noise>
				</ray>
				<plugin name="scan2" filename="libgazebo_ros_ray_sensor.so">
					<ros>
						<remapping>~/out:=scan2</remapping>
					</ros>
					<output_type>sensor_msgs/LaserScan</output_type>
					<frame_name>lidar_link2</frame_name>
				</plugin>
			</sensor>
		</link>

		<link name="camera_link">
			<pose>0.07 0 0.05 0 0 0</pose>
			<inertial>
				<mass>0.001</mass>
				<inertia>
					<ixx>0.00001</ixx>
					<ixy>0</ixy>
					<ixz>0</ixz>
					<iyy>0.00001</iyy>
					<iyz>0</iyz>
					<izz>0.00001</izz>
				</inertia>
			</inertial>
			<visual name="visual">
				<geometry>
					<box>
						<size>0.01 0.015 0.01</size>
					</box>
				</geometry>
			</visual>
			<!--
			<sensor name="camera1" type="camera">
				<update_rate>20.0</update_rate>
				<camera name="head">
					<horizontal_fov>1.3962634</horizontal_fov>
					<image>
						<width>800</width>
						<height>800</height>
						<format>R8G8B8</format>
					</image>
					<clip>
						<near>0.02</near>
						<far>300</far>
					</clip>
					<noise>
						<type>gaussian</type>
						<mean>0.0</mean>
						<stddev>0.007</stddev>
					</noise>
				</camera>
				<plugin name="camera_controller" filename="libgazebo_ros_camera.so">
					<alwaysOn>true</alwaysOn>
					<updateRate>0.0</updateRate>
					<cameraName>nav_omni4/camera1</cameraName>
					<imageTopicName>image_raw</imageTopicName>
					<cameraInfoTopicName>camera_info</cameraInfoTopicName>
					<frameName>camera_link</frameName>
					<hackBaseline>0.07</hackBaseline>
					<distortionK1>0.0</distortionK1>
					<distortionK2>0.0</distortionK2>
					<distortionK3>0.0</distortionK3>
					<distortionT1>0.0</distortionT1>
					<distortionT2>0.0</distortionT2>
				</plugin>
			</sensor>
			-->
			<sensor name="depth_camera" type="depth">
				<visualize>true</visualize>
				<update_rate>30.0</update_rate>
				<camera name="camera">
					<horizontal_fov>1.047198</horizontal_fov>
					<image>
						<width>640</width>
						<height>480</height>
						<format>R8G8B8</format>
					</image>
					<clip>
						<near>0.05</near>
						<far>3</far>
					</clip>
				</camera>
				<plugin name="depth_camera_controller" filename="libgazebo_ros_camera.so">
					<baseline>0.2</baseline>
					<alwaysOn>true</alwaysOn>
					<updateRate>0.0</updateRate>
					<frame_name>camera_depth_frame</frame_name>
					<pointCloudCutoff>0.5</pointCloudCutoff>
					<pointCloudCutoffMax>3.0</pointCloudCutoffMax>
					<distortionK1>0</distortionK1>
					<distortionK2>0</distortionK2>
					<distortionK3>0</distortionK3>
					<distortionT1>0</distortionT1>
					<distortionT2>0</distortionT2>
					<CxPrime>0</CxPrime>
					<Cx>0</Cx>
					<Cy>0</Cy>
					<focalLength>0</focalLength>
					<hackBaseline>0</hackBaseline>
				</plugin>
			</sensor>
		</link>

		<link name="dummy_link_1">
			<inertial>
				<mass>0.001</mass>
				<inertia>
					<ixx>0.00001</ixx>
					<ixy>0</ixy>
					<ixz>0</ixz>
					<iyy>0.00001</iyy>
					<iyz>0</iyz>
					<izz>0.00001</izz>
				</inertia>
			</inertial>
		</link>
		<link name="dummy_link_2">
			<inertial>
				<mass>0.001</mass>
				<inertia>
					<ixx>0.00001</ixx>
					<ixy>0</ixy>
					<ixz>0</ixz>
					<iyy>0.00001</iyy>
					<iyz>0</iyz>
					<izz>0.00001</izz>
				</inertia>
			</inertial>
		</link>

		<joint name="dummy_joint1" type="revolute">
			<parent>damped_omni4_model::body_link</parent>
			<child>dummy_link_1</child>
		</joint>
		<joint name="dummy_joint2" type="revolute">
			<parent>damped_omni4_model::body_link</parent>
			<child>dummy_link_2</child>
		</joint>

		<joint name="lidar_joint1" type="fixed">
			<parent>damped_omni4_model::body_link</parent>
			<child>lidar_link1</child>
		</joint>

		<joint name="lidar_joint2" type="fixed">
			<parent>damped_omni4_model::body_link</parent>
			<child>lidar_link2</child>
		</joint>

		<joint name="camera_joint" type="fixed">
			<parent>damped_omni4_model::body_link</parent>
			<child>camera_link</child>
		</joint>

		<!--
		<plugin name="wheel_odometry" filename="libgazebo_ros_wheel_odometry.so">
			<publish_odom_msg>true</publish_odom_msg>
			<publish_tf>true</publish_tf>
			<robot_base_frame>base_link</robot_base_frame>
		</plugin>
		-->

      <plugin name="turtlebot3_diff_drive" filename="libgazebo_ros_diff_drive.so">

        <update_rate>30</update_rate>

        <!-- wheels -->
        <left_joint>dummy_joint1</left_joint>
        <right_joint>dummy_joint2</right_joint>

        <!-- kinematics -->
        <wheel_separation>0.287</wheel_separation>
        <wheel_diameter>0.066</wheel_diameter>

        <!-- limits -->
        <max_wheel_torque>0</max_wheel_torque>
        <max_wheel_acceleration>0.0</max_wheel_acceleration>

        <command_topic>cmd_vel</command_topic>

        <!-- output -->
        <publish_odom>true</publish_odom>
        <publish_odom_tf>true</publish_odom_tf>
        <publish_wheel_tf>false</publish_wheel_tf>

        <odometry_topic>odom</odometry_topic>
        <odometry_frame>odom</odometry_frame>
        <robot_base_frame>base_link</robot_base_frame>

      </plugin>


	</model>
</sdf>
