<?xml version='1.0'?>
<sdf version='1.6' xmlns:xacro="http://www.ros.org/wiki/xacro">
	<model name='indep_steer_model'>

		<pose>0 0 0.1 0 0 0</pose>

		<link name='body_link'>
			<pose>0 0 0.02 0 0 0</pose>
			<inertial>
				<mass>0.07862944645</mass>
				<pose>0 0 0 0 0 0</pose>
				<inertia>
					<ixx>0.00018035985530754</ixx>
					<ixy>0</ixy>
					<ixz>0</ixz>
					<iyy>0.00018035985530754</iyy>
					<iyz>0</iyz>
					<izz>0.00018945961663220</izz>
				</inertia>
			</inertial>
			<visual name='visual'>
				<pose>0 0 0 0 0 0</pose>
				<geometry>
					<box>
						<size>0.14 0.14 0.015</size>
					</box>
				</geometry>
				<material>
					<lighting>true</lighting>
					<script>
						<uri>file://media/materials/scripts/gazebo.material</uri>
						<name>Gazebo/Grey</name>
					</script>
					<ambient>1 1 1 1</ambient>
					<diffuse>0.7 0.7 0.7 1</diffuse>
					<specular>0.01 0.01 0.01 1</specular>
					<emissive>0 0 0 1</emissive>
					<shader type='vertex'>
						<normal_map>__default__</normal_map>
					</shader>
				</material>
			</visual>
			<collision name='collision'>
				<laser_retro>0</laser_retro>
				<max_contacts>10</max_contacts>
				<pose>0 0 0 0 0 0</pose>
				<geometry>
					<box>
						<size>0.14 0.14 0.015</size>
					</box>
				</geometry>
				<surface>
					<friction>
						<ode>
							<mu>1</mu>
							<mu2>1</mu2>
							<fdir1>0 0 0</fdir1>
							<slip1>0</slip1>
							<slip2>0</slip2>
						</ode>
						<torsional>
							<coefficient>1</coefficient>
							<patch_radius>0</patch_radius>
							<surface_radius>0</surface_radius>
							<use_patch_radius>true</use_patch_radius>
							<ode>
								<slip>0</slip>
							</ode>
						</torsional>
					</friction>
					<bounce>
						<restitution_coefficient>0</restitution_coefficient>
						<threshold>1e+06</threshold>
					</bounce>
					<contact>
						<collide_without_contact>false</collide_without_contact>
						<collide_bitmask>1</collide_bitmask>
						<ode>
							<soft_cfm>0</soft_cfm>
							<soft_erp>0.2</soft_erp>
							<kp>1e+13</kp>
							<kd>1</kd>
							<max_vel>0.01</max_vel>
							<min_depth>0</min_depth>
						</ode>
						<bullet>
							<split_impulse>true</split_impulse>
							<split_impulse_penetration_threshold>-0.01</split_impulse_penetration_threshold>
							<soft_cfm>0</soft_cfm>
							<soft_erp>0.2</soft_erp>
							<kp>1e+13</kp>
							<kd>1</kd>
						</bullet>
					</contact>
				</surface>
			</collision>
		</link>

		<include>
			<name>unicycle_wheel_front_left_model</name>
			<uri>model://unicycle_wheel</uri>
			<pose>${0.12*cos(pi*1/4)} ${0.12*sin(pi*1/4)} 0 0 0 0</pose>
		</include>

		<include>
			<name>unicycle_wheel_back_left_model</name>
			<uri>model://unicycle_wheel</uri>
			<pose>${0.12*cos(pi*3/4)} ${0.12*sin(pi*3/4)} 0 0 0 0</pose>
		</include>

		<include>
			<name>unicycle_wheel_back_right_model</name>
			<uri>model://unicycle_wheel</uri>
			<pose>${0.12*cos(pi*5/4)} ${0.12*sin(pi*5/4)} 0 0 0 0</pose>
		</include>

		<include>
			<name>unicycle_wheel_front_right_model</name>
			<uri>model://unicycle_wheel</uri>
			<pose>${0.12*cos(pi*7/4)} ${0.12*sin(pi*7/4)} 0 0 0 0</pose>
		</include>

		<xacro:macro name="body_uni_conn" params="prefix uni_link">
			<joint name='${prefix}_linear_joint' type='prismatic'>
				<parent>body_link</parent>
				<child>${uni_link}</child>
				<axis>
					<limit>
						<lower>-0.004</lower>
						<upper>0.004</upper>
					</limit>
					<dynamics>
						<spring_reference>0.0</spring_reference>
						<spring_stiffness>300.0</spring_stiffness>
						<damping>0.2</damping>
					</dynamics>
					<xyz>0 0 1</xyz>
				</axis>
			</joint>
		</xacro:macro>

		<xacro:body_uni_conn prefix="front_left" uni_link="unicycle_wheel_front_left_model::unicycle_wheel_base_link"/>
		<xacro:body_uni_conn prefix="front_right" uni_link="unicycle_wheel_front_right_model::unicycle_wheel_base_link"/>
		<xacro:body_uni_conn prefix="back_left" uni_link="unicycle_wheel_back_left_model::unicycle_wheel_base_link"/>
		<xacro:body_uni_conn prefix="back_right" uni_link="unicycle_wheel_back_right_model::unicycle_wheel_base_link"/>

		<plugin name="indep_steer_drive" filename="libgazebo_ros_indep_steer_drive.so">
			<unicycle_joints>
				<steer>unicycle_wheel_front_left_model::unicycle_steering_joint</steer>
				<axle>unicycle_wheel_front_left_model::unicycle_wheel_axle_joint</axle>
			</unicycle_joints>
			<unicycle_joints>
				<steer>unicycle_wheel_back_left_model::unicycle_steering_joint</steer>
				<axle>unicycle_wheel_back_left_model::unicycle_wheel_axle_joint</axle>
			</unicycle_joints>
			<unicycle_joints>
				<steer>unicycle_wheel_back_right_model::unicycle_steering_joint</steer>
				<axle>unicycle_wheel_back_right_model::unicycle_wheel_axle_joint</axle>
			</unicycle_joints>
			<unicycle_joints>
				<steer>unicycle_wheel_front_right_model::unicycle_steering_joint</steer>
				<axle>unicycle_wheel_front_right_model::unicycle_wheel_axle_joint</axle>
			</unicycle_joints>
			<wheel_radius>0.05</wheel_radius>
		</plugin>
	</model>
</sdf>
